Workbook

Sheet Data
A1: Depth at which drilling begins x (meters) | B1: Time to drill 5 meters y (minutes)
A2: 0 | B2: 4.9
A3: 25 | B3: 7.41
A4: 50 | B4: 6.19
A5: 75 | B5: 5.57
A6: 100 | B6: 5.17
A7: 125 | B7: 6.89
A8: 150 | B8: 7.05
A9: 175 | B9: 7.11
A10: 200 | B10: 6.19
A11: 225 | B11: 8.28
A12: 250 | B12: 4.84
A13: 275 | B13: 8.29
... A18: 395 | B18: 11.02

Sheet Regression Analysis
B2: Regression
B3: Regression Model | C3: Linear
B5: LINEST raw output
B6: {=LINEST(Data!$B$2:$B$18 , Data!$A$2:$A$18 , 1 , 1)} -> 0.01438785 | C6: 4.7896028
B7: 0.0028472223 | C7: 0.66631192
B8: 0.62995653 | C8: 1.4321939
B9: 25.535778 | C9: 15
B10: 52.378462 | C10: 30.767691
B12: Regression Statistics
B13: R^2 | C13: ='Regression Analysis'!$B$8 -> 0.62995653
B14: Standard Error | C14: ='Regression Analysis'!$C$8 -> 1.4321939
B15: Count of X variables | C15: =1 -> 1
B16: Observations | C16: =17 -> 17
B17: Adjusted R^2 | C17: =1 - (1 - 'Regression Analysis'!$B$8)*('Regression Analysis'!$C$16 - 1)/('Regression Analysis'!$C$16 - 'Regression Analysis'!$C$15 - 1) -> 0.60528696
B19: Analysis of Variance (ANOVA)
C20: df | D20: SS | E20: MS | F20: F | G20: Significance F
B21: Regression | C21: ='Regression Analysis'!$C$15 -> 1 | D21: ='Regression Analysis'!$B$10 -> 52.378462 | E21: ='Regression Analysis'!$B$10 / 'Regression Analysis'!$C$21 -> 52.378462 | F21: ='Regression Analysis'!$B$9 -> 25.535778 | G21: =FDIST('Regression Analysis'!$B$9 , 'Regression Analysis'!$C$21 , 'Regression Analysis'!$C$9) -> 0.00014285586
B22: Residual | C22: ='Regression Analysis'!$C$9 -> 15 | D22: ='Regression Analysis'!$C$10 -> 30.767691 | E22: ='Regression Analysis'!$C$10 / 'Regression Analysis'!$C$9 -> 2.0511794
B23: Total | C23: ='Regression Analysis'!$C$21 + 'Regression Analysis'!$C$9 -> 16 | D23: ='Regression Analysis'!$B$10 + 'Regression Analysis'!$C$10 -> 83.146153
B25: Confidence level | C25: 0.95
C27: Coefficients | D27: Standard Error | E27: t-Statistic | F27: P-value | G27: =_xlfn.CONCAT("Lower " , INT('Regression Analysis'!$C$25 * 100) , "%") -> Lower 95% | H27: =_xlfn.CONCAT("Upper " , INT('Regression Analysis'!$C$25 * 100) , "%") -> Upper 95%
B28: ="Intercept" -> Intercept | C28: {=INDEX('Regression Analysis'!$B$6:$C$6, 1 , ROW('Regression Analysis'!$C$29)+1 - ROW())} -> 4.7896028 | D28: {=INDEX('Regression Analysis'!$B$7:$C$7, 1 , ROW('Regression Analysis'!$D$29)+1 - ROW())} -> 0.66631192 | E28: {='Regression Analysis'!$C$28:$C$29 / 'Regression Analysis'!$D$28:$D$29} -> 7.1882292 | F28: {=TDIST(ABS('Regression Analysis'!$E$28:$E$29) , 'Regression Analysis'!$C$9 , 2 )} -> 3.1334672e-06 | G28: {='Regression Analysis'!$C$28:$C$29 - 'Regression Analysis'!$D$28:$D$29 * TINV(1 - 'Regression Analysis'!$C$25 , 'Regression Analysis'!$C$9)} -> 3.3693926 | H28: {='Regression Analysis'!$C$28:$C$29 + 'Regression Analysis'!$D$28:$D$29 * TINV(1 - 'Regression Analysis'!$C$25 , 'Regression Analysis'!$C$9)} -> 6.209813
B29: =Data!$A$1 -> Depth at which drilling begins x (meters) | C29: 0.01438785 | D29: 0.0028472223 | E29: 5.0532938 | F29: 0.00014285586 | G29: 0.0083191399 | H29: 0.020456561
B31: =Data!$A$1 -> Depth at which drilling begins x (meters) | C31: Predicted Y | D31: =Data!$B$1 -> Time to drill 5 meters y (minutes) | E31: Residual
B32: {=Data!$A$2:$A$18} -> 0 | C32: {=MMULT('Regression Analysis'!$B$32:$B$48 , 'Regression Analysis'!$C$29) + 'Regression Analysis'!$C$28} -> 4.7896028 | D32: {=Data!$B$2:$B$18} -> 4.9 | E32: {='Regression Analysis'!$D$32:$D$48 - 'Regression Analysis'!$C$32:$C$48} -> 0.1103972
B33: 25 | C33: 5.1492991 | D33: 7.41 | E33: 2.2607009
B34: 50 | C34: 5.5089953 | D34: 6.19 | E34: 0.68100467
B35: 75 | C35: 5.8686916 | D35: 5.57 | E35: -0.29869159
B36: 100 | C36: 6.2283879 | D36: 5.17 | E36: -1.0583879
B37: 125 | C37: 6.5880841 | D37: 6.89 | E37: 0.30191589
B38: 150 | C38: 6.9477804 | D38: 7.05 | E38: 0.10221963
B39: 175 | C39: 7.3074766 | D39: 7.11 | E39: -0.19747664
B40: 200 | C40: 7.6671729 | D40: 6.19 | E40: -1.4771729
B41: 225 | C41: 8.0268692 | D41: 8.28 | E41: 0.25313084
B42: 250 | C42: 8.3865654 | D42: 4.84 | E42: -3.5465654
B43: 275 | C43: 8.7462617 | D43: 8.29 | E43: -0.45626168
B44: 300 | C44: 9.1059579 | D44: 8.91 | E44: -0.19595794
... B48: 395 | C48: 10.472804 | D48: 11.02 | E48: 0.54719626

Sheet Questions & Answers
A1: a) Construct a scatterplot for the data.
A28: b) Find the least squares prediction equation using the calculation formulas.
B29: x | C29: y | D29: x2 | E29: y2 | F29: xy | I29: Number of data points
B30: 0 | C30: 4.9 | D30: =B30^2 -> 0 | E30: =C30^2 -> 24.01 | F30: =B30*C30 -> 0 | I30: n | J30: =COUNT(B30:B46) -> 17
B31: 25 | C31: 7.41 | D31: =B31^2 -> 625 | E31: =C31^2 -> 54.9081 | F31: =B31*C31 -> 185.25
B32: 50 | C32: 6.19 | D32: =B32^2 -> 2500 | E32: =C32^2 -> 38.3161 | F32: =B32*C32 -> 309.5
B33: 75 | C33: 5.57 | D33: =B33^2 -> 5625 | E33: =C33^2 -> 31.0249 | F33: =B33*C33 -> 417.75 | I33: Means
B34: 100 | C34: 5.17 | D34: =B34^2 -> 10000 | E34: =C34^2 -> 26.7289 | F34: =B34*C34 -> 517 | I34: x_bar | J34: =AVERAGE(B30:B46) -> 199.70588
B35: 125 | C35: 6.89 | D35: =B35^2 -> 15625 | E35: =C35^2 -> 47.4721 | F35: =B35*C35 -> 861.25 | I35: y_bar | J35: =AVERAGE(C30:C46) -> 7.6629412
B36: 150 | C36: 7.05 | D36: =B36^2 -> 22500 | E36: =C36^2 -> 49.7025 | F36: =B36*C36 -> 1057.5
B37: 175 | C37: 7.11 | D37: =B37^2 -> 30625 | E37: =C37^2 -> 50.5521 | F37: =B37*C37 -> 1244.25
B38: 200 | C38: 6.19 | D38: =B38^2 -> 40000 | E38: =C38^2 -> 38.3161 | F38: =B38*C38 -> 1238 | I38: Sum of Squares
B39: 225 | C39: 8.28 | D39: =B39^2 -> 50625 | E39: =C39^2 -> 68.5584 | F39: =B39*C39 -> 1863 | I39: Ssxy | J39: =F47-J30*J34*J35 -> 3640.4647
B40: 250 | C40: 4.84 | D40: =B40^2 -> 62500 | E40: =C40^2 -> 23.4256 | F40: =B40*C40 -> 1210 | I40: Ssxx | J40: =D47-J30*J34^2 -> 253023.53
B41: 275 | C41: 8.29 | D41: =B41^2 -> 75625 | E41: =C41^2 -> 68.7241 | F41: =B41*C41 -> 2279.75 | I41: Ssyy | J41: =E47-J30*J35^2 -> 83.146153
B42: 300 | C42: 8.91 | D42: =B42^2 -> 90000 | E42: =C42^2 -> 79.3881 | F42: =B42*C42 -> 2673
B43: 325 | C43: 8.54 | D43: =B43^2 -> 105625 | E43: =C43^2 -> 72.9316 | F43: =B43*C43 -> 2775.5
B44: 350 | C44: 11.79 | D44: =B44^2 -> 122500 | E44: =C44^2 -> 139.0041 | F44: =B44*C44 -> 4126.5 | I44: Least Squares Estimates
B45: 375 | C45: 12.12 | D45: =B45^2 -> 140625 | E45: =C45^2 -> 146.8944 | F45: =B45*C45 -> 4545 | I45: Β1_hat | J45: =J39/J40 -> 0.01438785
B46: 395 | C46: 11.02 | D46: =B46^2 -> 156025 | E46: =C46^2 -> 121.4404 | F46: =B46*C46 -> 4352.9 | I46: Β0_hat | J46: =J35-J45*J34 -> 4.7896028
B47: =SUM(B30:B46) -> 3395 | C47: =SUM(C30:C46) -> 130.27 | D47: =SUM(D30:D46) -> 931025 | E47: =SUM(E30:E46) -> 1081.3975 | F47: =SUM(F30:F46) -> 29656.15
A49: c) Interpret the values of β 0 and β1 .
B50: - The value of B0_hat tells that the the expected value of y when x = 0 is 4.7896; that
B51: is, the average time it takes to drill 5 meters of rock when the depth is 0 meters is 4.7896 minutes.
B52: - The value of B1_hat tells two things: the relationship between the two variables is positive; that is,
B53: the time it takes to drill 5 meters of rock increases as the depth increases, and it increases by 0.0144
B54: minutes.
A56: d) Is there evidence that dry drill time y increases with depth x? Test using α = 0.10.
B57: x | C57: y | D57: y_hat | E57: y – y_hat | F57: (y – y_hat)2
B58: 0 | C58: 4.9 | D58: =$J$46+$J$45*B58 -> 4.7896028 | E58: =C58-D58 -> 0.1103972 | F58: =E58^2 -> 0.012187541
B59: 25 | C59: 7.41 | D59: =$J$46+$J$45*B59 -> 5.1492991 | E59: =C59-D59 -> 2.2607009 | F59: =E59^2 -> 5.1107687
B60: 50 | C60: 6.19 | D60: =$J$46+$J$45*B60 -> 5.5089953 | E60: =C60-D60 -> 0.68100467 | F60: =E60^2 -> 0.46376736
B61: 75 | C61: 5.57 | D61: =$J$46+$J$45*B61 -> 5.8686916 | E61: =C61-D61 -> -0.29869159 | F61: =E61^2 -> 0.089216665
B62: 100 | C62: 5.17 | D62: =$J$46+$J$45*B62 -> 6.2283879 | E62: =C62-D62 -> -1.0583879 | F62: =E62^2 -> 1.1201848
B63: 125 | C63: 6.89 | D63: =$J$46+$J$45*B63 -> 6.5880841 | E63: =C63-D63 -> 0.30191589 | F63: =E63^2 -> 0.091153203
B64: 150 | C64: 7.05 | D64: =$J$46+$J$45*B64 -> 6.9477804 | E64: =C64-D64 -> 0.10221963 | F64: =E64^2 -> 0.010448852
B65: 175 | C65: 7.11 | D65: =$J$46+$J$45*B65 -> 7.3074766 | E65: =C65-D65 -> -0.19747664 | F65: =E65^2 -> 0.038997022
B66: 200 | C66: 6.19 | D66: =$J$46+$J$45*B66 -> 7.6671729 | E66: =C66-D66 -> -1.4771729 | F66: =E66^2 -> 2.1820398
B67: 225 | C67: 8.28 | D67: =$J$46+$J$45*B67 -> 8.0268692 | E67: =C67-D67 -> 0.25313084 | F67: =E67^2 -> 0.064075223
B68: 250 | C68: 4.84 | D68: =$J$46+$J$45*B68 -> 8.3865654 | E68: =C68-D68 -> -3.5465654 | F68: =E68^2 -> 12.578126
...
